Workbook

Sheet Summary
A1: Black-Box Test Cases: Rider Modules (R1–R7)
A2: Multi-role e-commerce and logistics platform (Buyer, Seller, Logistics, Rider)
A4: Test run details
A5: System under test | B5: BoomBuy (boombuy.store)
A6: Version / build | B6: Branch mobile-app, build a5a130d
A7: Test environment (browser, device) | B7: Automated PHPUnit feature tests (Laravel, PHP 8.5) on Windows 11; Chrome-based browser for the pages
A8: Tester
A9: Date tested | B9: 2026-10-19
A11: Results by module
A12: Module (sheet) | B12: Total test cases | C12: Pass | D12: Fail | E12: Blocked | F12: Not Run | G12: Pass rate (Pass / Total)
A13: R1 Profile & Vehicle | B13: =COUNTA('R1 Profile & Vehicle'!$A$2:$A$200) | C13: =COUNTIF('R1 Profile & Vehicle'!$L$2:$L$200,"Pass") | D13: =COUNTIF('R1 Profile & Vehicle'!$L$2:$L$200,"Fail") | E13: =COUNTIF('R1 Profile & Vehicle'!$L$2:$L$200,"Blocked") | F13: =COUNTIF('R1 Profile & Vehicle'!$L$2:$L$200,"Not Run") | G13: =IF(B13=0,0,C13/B13)
A14: R2 Availability | B14: =COUNTA('R2 Availability'!$A$2:$A$200) | C14: =COUNTIF('R2 Availability'!$L$2:$L$200,"Pass") | D14: =COUNTIF('R2 Availability'!$L$2:$L$200,"Fail") | E14: =COUNTIF('R2 Availability'!$L$2:$L$200,"Blocked") | F14: =COUNTIF('R2 Availability'!$L$2:$L$200,"Not Run") | G14: =IF(B14=0,0,C14/B14)
A15: R3 Job Assignment | B15: =COUNTA('R3 Job Assignment'!$A$2:$A$200) | C15: =COUNTIF('R3 Job Assignment'!$L$2:$L$200,"Pass") | D15: =COUNTIF('R3 Job Assignment'!$L$2:$L$200,"Fail") | E15: =COUNTIF('R3 Job Assignment'!$L$2:$L$200,"Blocked") | F15: =COUNTIF('R3 Job Assignment'!$L$2:$L$200,"Not Run") | G15: =IF(B15=0,0,C15/B15)
A16: R4 Pickup | B16: =COUNTA('R4 Pickup'!$A$2:$A$200) | C16: =COUNTIF('R4 Pickup'!$L$2:$L$200,"Pass") | D16: =COUNTIF('R4 Pickup'!$L$2:$L$200,"Fail") | E16: =COUNTIF('R4 Pickup'!$L$2:$L$200,"Blocked") | F16: =COUNTIF('R4 Pickup'!$L$2:$L$200,"Not Run") | G16: =IF(B16=0,0,C16/B16)
A17: R5 Delivery | B17: =COUNTA('R5 Delivery'!$A$2:$A$200) | C17: =COUNTIF('R5 Delivery'!$L$2:$L$200,"Pass") | D17: =COUNTIF('R5 Delivery'!$L$2:$L$200,"Fail") | E17: =COUNTIF('R5 Delivery'!$L$2:$L$200,"Blocked") | F17: =COUNTIF('R5 Delivery'!$L$2:$L$200,"Not Run") | G17: =IF(B17=0,0,C17/B17)
A18: R6 Failed Delivery | B18: =COUNTA('R6 Failed Delivery'!$A$2:$A$200) | C18: =COUNTIF('R6 Failed Delivery'!$L$2:$L$200,"Pass") | D18: =COUNTIF('R6 Failed Delivery'!$L$2:$L$200,"Fail") | E18: =COUNTIF('R6 Failed Delivery'!$L$2:$L$200,"Blocked") | F18: =COUNTIF('R6 Failed Delivery'!$L$2:$L$200,"Not Run") | G18: =IF(B18=0,0,C18/B18)
A19: R7 Earnings & COD | B19: =COUNTA('R7 Earnings & COD'!$A$2:$A$200) | C19: =COUNTIF('R7 Earnings & COD'!$L$2:$L$200,"Pass") | D19: =COUNTIF('R7 Earnings & COD'!$L$2:$L$200,"Fail") | E19: =COUNTIF('R7 Earnings & COD'!$L$2:$L$200,"Blocked") | F19: =COUNTIF('R7 Earnings & COD'!$L$2:$L$200,"Not Run") | G19: =IF(B19=0,0,C19/B19)
A20: Total | B20: =SUM(B13:B19) | C20: =SUM(C13:C19) | D20: =SUM(D13:D19) | E20: =SUM(E13:E19) | F20: =SUM(F13:F19) | G20: =IF(B20=0,0,C20/B20)
A22: How to use this workbook
A23: 1. Riders need orders that sellers have marked Ready for Pickup. Run with the Logistics test set.
A24: 2. Strict pass rule: a case passes only if EVERY point in its Expected Result is true. If any point is false, or something happens that the Expected Result does not mention (an extra record, a stock change, a wrong notification, a console error, a 500 page), mark it Fail.
A25: 3. Check side effects, not just the screen: after each case, confirm the stock, order status, voucher usage, balances and the other roles' views named in the Expected Result. 'Nothing is saved' means the record is missing after a page refresh.
A26: 4. Error messages must appear next to the field (or at the top of the form) and say what is wrong and how to fix it. A generic 'Something went wrong', a blank page, or a 500 error is a Fail even when the action was correctly blocked.
A27: 5. For 'Error Guessing' security cases, a correct block shows a 403 page, a 'not found' page or a redirect, and shows NO data from the other user's record anywhere on the page.
A28: 6. Read the Assumptions sheet first. Rules A2 to A8 are the seven rules the module plan says must be agreed before testing; adjust any case whose rule differs from your system.
A29: 7. Seed the accounts, products, vouchers and shipping rates on the Test Data sheet before running the cases. Emails use example.com; read them from a mail catcher such as Mailtrap.
A30: 8. Test Case IDs follow <ROLE>-<MODULE>-<NNN>. Each module has positive, negative and boundary cases.
A31: 9. Fill in only the yellow cells: Actual Result, Status and Remarks. Pick the Status from the dropdown (Pass, Fail, Blocked, Not Run).
A32: 10. Pass = actual matches expected. Fail = it does not (describe what happened and add a screenshot or bug number in Remarks). Blocked = the case could not be run, for example because an earlier case failed.
A33: 11. The Results by module table above updates automatically from the Status column.
A35: Black-box techniques used
A36: Equivalence Partitioning | B36: Inputs are grouped into valid and invalid classes, and one value from each class is tested.
A37: Boundary Value Analysis | B37: Values at and just beyond a limit are tested, for example ₱0.99, ₱1.00 and ₱1.01 for a ₱1.00 minimum price.
A38: Decision Table | B38: Combinations of conditions are tested, for example which vouchers can stack.
A39: State Transition | B39: Changes in order or shipment status are tested, including transitions that must be blocked.
A40: Use Case Testing | B40: A complete user flow is tested from start to finish with valid data.
A41: Error Guessing | B41: Likely mistakes are tested based on experience, for example double-clicking Place Order or editing an ID in the URL.

Sheet Assumptions
A1: Assumptions used in the test cases
A2: These rules are assumptions modeled on Philippine marketplaces, not taken from your actual system. Rules A2 to A8 are the seven rules the module plan says must be agreed before testing; A25 to A37 fix the limits the strict expected results depend on. Write your real rule in column D where it differs, then filter the Assumption Ref column on each module sheet to find the test cases to adjust.
A4: Ref | B4: Topic | C4: Assumed rule | D4: Your system's actual rule (fill in if different)
A5: A1 | B5: Test accounts | C5: The accounts on the Test Data sheet already exist and are Active or Approved (they are the accounts created in the Account Creation test set). Seller 3 is Pending Approval and Rider 3 is Suspended, for the negative cases. Reset the seeded products, stock and vouchers to their Test Data values before each module. | D5: Same accounts, seeded by the automated tests (ModuleSheetWorld): Riders 1-3 under Logistics 1 (Bilis Hatid Express Inc., Quezon City Sorting Center); Rider 3 Suspended.
A6: A2 | B6: Voucher stacking (rule 1) | C6: Per order: at most 1 store voucher per store, plus 1 platform voucher, plus 1 shipping voucher. Selecting a second voucher of the same type replaces the first; it never stacks.
A7: A3 | B7: Stock deduction (rule 2) | C7: Stock is deducted when the order is placed, for every payment method. It is restored when the order is cancelled (by buyer, seller or auto-cancel). For a Return-to-Sender or returned parcel, stock is restored when the seller confirms receipt. Stock can never go below 0.
A8: A4 | B8: Sale + voucher (rule 3) | C8: Vouchers apply to items already on sale. Minimum spend is checked against the price actually paid (the sale or flash price), not the original price.
A9: A5 | B9: Flash sales (rule 4) | C9: Sellers create flash sales for their own products in fixed time slots. When a product is in both a store sale and a flash sale, the flash price wins while flash quantity remains. Units beyond the remaining flash quantity in the same order are charged at the store sale price, or the regular price if there is no sale, and are shown on a separate line.
A10: A6 | B10: Cancellation window and auto-cancel (rule 5) | C10: A buyer can cancel until the seller marks the order Ready for Pickup; after that there is no cancel option at all. A seller can cancel until the parcel is Picked Up. Unpaid e-wallet or card orders auto-cancel exactly 1 hour after the order is placed.
A11: A7 | B11: Variation limits and category depth (rule 6) | C11: A product has at most 2 variation types, with 1 to 20 options per type. Store categories have at most 2 levels (category and subcategory). A product can belong to up to 3 store categories.
A12: A8 | B12: Voucher funding (rule 7) | C12: Store vouchers, sale discounts, flash sales and bundle discounts are seller-funded. Platform vouchers and shipping vouchers are platform-funded and never reduce the seller's earnings. A platform voucher on a multi-store checkout is split across the store orders in proportion to each store's merchandise subtotal, rounded to the centavo, with any rounding remainder given to the largest store. When only some items in an order are refunded, the store voucher is split across the items in proportion to their price, and the refund is the item price minus its voucher share.
A13: A9 | B13: Platform commission and rounding | C13: Commission is 5% of the item subtotal after seller-funded discounts. Shipping fees are not part of the seller's gross sales. All money is rounded to 2 decimals (half up) per order.
A14: A10 | B14: Order status flow | C14: Buyer tabs: To Pay → To Ship → To Receive → Completed (or Cancelled, Return/Refund). Seller: New → Accepted → Packed → Ready for Pickup. Shipment: Ready for Pickup → Assigned → Picked Up → At Hub → Out for Delivery → Delivered (or Failed Delivery → Return to Sender → Returned to Sender). No status can be skipped or moved backwards except by a logged Logistics override. | D14: BoomBuy status names (ERP Flow): Assigned = Pickup Assigned / Assigned for Delivery, At Hub = At Sorting Center, Failed Delivery = Delivery Failed, Return to Sender is shown for a refused parcel or the 3rd failed attempt.
A15: A11 | B15: Order completion and return window | C15: The buyer clicks Order Received, or the order completes automatically 7 days (168 hours) after Delivered. A return or refund can be requested only after Delivered, within those 7 days and before the order is Completed.
A16: A12 | B16: Reviews | C16: A review is allowed only for Completed orders, within 30 days of completion, one review per item. Stars (1–5) are required; text is optional, up to 500 characters; up to 5 photos. It can be edited once within the 30 days. The seller can post one reply per review and edit it; the seller cannot delete or hide a buyer's review.
A17: A13 | B17: Failed delivery | C17: Up to 3 delivery attempts. A reason from the list (Buyer not home, Wrong address, Refused) is required for every failed attempt. After the 3rd failed attempt, or immediately when the reason is Refused, the parcel is marked Return to Sender. | D17: Same rule (3 attempts; Refused = straight to Return to Sender). BoomBuy reason list: Buyer not available (= not home), Buyer unreachable by phone, Wrong or incomplete address, Buyer refused the parcel (= Refused), Other.
A18: A14 | B18: Rider job rules | C18: A job offer expires after 60 seconds. A declined or expired offer goes to the next nearest eligible rider; after 3 riders decline or let it expire, the job goes to the Unassigned queue for manual assignment. A rider holds at most 3 active jobs. Only Active, Online riders receive offers. | D18: Same rule. 'Nearest' = the rider whose delivery area is the seller's town, then the seller's province, then fewest jobs. Riders can still also accept pickups from their 'Pickup requests near you' list (ERP).
A19: A15 | B19: Seller earnings and payout | C19: Earnings move from Pending to Available only when an order is Completed. Cancelled, returned and refunded amounts are excluded. A payout request must be at least ₱100.00 and no more than the Available balance, and only one payout request can be pending at a time.
A20: A16 | B20: Image upload rule | C20: Product, logo, banner, review, return, chat and proof-of-delivery images: JPG or PNG only (checked by file content, not just the extension), maximum 5 MB each. A product has 1 to 9 images.
A21: A17 | B21: Price and quantity rule | C21: Prices range from ₱1.00 to ₱1,000,000.00 with up to 2 decimal places. Stock and quantities are whole numbers from 0 to 99,999.
A22: A18 | B22: Store vacation and verification | C22: In vacation mode, products stay visible but Add to Cart and Buy Now are disabled with an 'On vacation' label, and checkout of items already in carts is blocked. A seller that is not Approved can save products only as drafts and cannot publish.
A23: A19 | B23: Deleting categories and products | C23: Deleting a store category that still has products moves those products to 'Uncategorized'. Deleting a parent category also deletes its subcategories. A product or a variant with unfinished orders cannot be deleted; other deletes are soft deletes, so order history still shows the product's name, image and price.
A24: A20 | B24: Shipping fee | C24: Shipping is charged per store, using the rate table on the Test Data sheet. Chargeable weight is the total actual weight of that store's items in the order, rounded up to the next whole kg. Rate changes apply only to checkouts started after the change.
A25: A21 | B25: Voucher return on cancellation | C25: A voucher used on a cancelled order is returned to the buyer's wallet if it has not yet expired, and its usage count is reduced by 1. A voucher is not returned for a refunded (returned) order.
A26: A22 | B26: Session and access | C26: Each role can open only its own pages; other roles get 403 or a redirect, for both pages and direct API requests. Users can open only their own records (orders, products, shipments, riders). A session expires after 30 minutes of inactivity. | D26: A rider sees and updates only their own jobs and profile; other riders' or companies' records are refused (403, not found or an error message).
A27: A23 | B27: Notifications | C27: Every order or shipment status change sends an in-app notification to each role involved, and to no one else. Emails use example.com and are read from the mail catcher.
A28: A24 | B28: COD remittance | C28: Riders remit the full COD collected to their logistics company by the end of the day. Only the logistics company can confirm a remittance. Any difference between collected and remitted COD is flagged on the reconciliation screen.
A29: A25 | B29: Text field limits | C29: Store name 3–30 characters (unique, not case-sensitive, spaces trimmed). Store description up to 500. Store category name 1–50 (unique per store, not case-sensitive, trimmed). Product name 5–120. Product description 20–3,000. Note to seller up to 200. Chat message 1–1,000. Free-text reasons (cancel, reject, override, suspend) 10–300. HTML or script entered in any field is shown as plain text.
A30: A26 | B30: Voucher code rule | C30: 4 to 12 letters and digits, no spaces or symbols, saved in uppercase. Codes are unique across the whole platform. Buyers can type the code in any case.
A31: A27 | B31: Editing vouchers after claim | C31: Once any buyer has claimed a voucher, the seller can only extend its end date or raise its usage limit; all other fields are locked. Ending a voucher removes it from the wallets of buyers who have not used it; orders already placed keep their discount.
A32: A28 | B32: Store sales | C32: A product can be in only one store sale at a time; overlapping schedules are rejected. A running sale's discount can be edited and applies immediately to new orders; End Now ends it at once. Orders already placed keep the price paid.
A33: A29 | B33: Low-stock alert | C33: An alert is shown when a product's or variant's stock reaches 5 or fewer, once per crossing (it does not repeat until stock goes above 5 and drops again).
A34: A30 | B34: Address book | C34: Up to 10 addresses per buyer. The default address cannot be deleted until another address is made default. Orders keep a copy of the address at order time, so editing or deleting an address does not change existing orders.
A35: A31 | B35: Return and refund requests | C35: Reason from the list, a description of 10–500 characters, and 1 to 5 photos (JPG or PNG, 5 MB each) are required. The seller must respond within 3 days or the request is auto-approved. A rejected request can be escalated to a dispute once, within 3 days. The refund goes to the original payment method; for COD orders, to the buyer's refund account.
A36: A32 | B36: Proof of delivery | C36: Delivered needs a photo (JPG or PNG) and the 6-digit delivery OTP shown in the buyer's app once the parcel is Out for Delivery. After 5 wrong OTP entries, OTP entry on that job is locked for 15 minutes. | D36: Same rule: the 6-digit OTP shows in the buyer's order once Out for Delivery; 5 wrong entries lock OTP entry for 15 minutes.
A37: A33 | B37: Rider pay | C37: ₱50.00 per successful delivery, ₱30.00 per completed pickup, ₱0.00 for a failed attempt. Pay is not reduced by COD. | D37: Rider pay: ₱30.00 per pickup; a delivery earns the platform base delivery fee (₱50.00 with the sheet's rates); ₱0.00 for a failed attempt.
A38: A34 | B38: Dispatch and reassignment | C38: Auto-assign offers a job to the nearest Online, Active rider of the same company with fewer than 3 active jobs. Logistics can reassign a job only before it is Picked Up. Suspending a rider returns their not-yet-picked-up jobs to the Unassigned queue; parcels already picked up stay with that rider.
A39: A35 | B39: Audit log | C39: Every manual status override, rider approval or suspension, rate change and remittance confirmation is logged with user, date and time, old value, new value and reason. Log entries cannot be edited or deleted from the UI.
A40: A36 | B40: Report export | C40: Reports export as CSV and XLSX. Exported rows and totals equal the on-screen rows and totals for the same filter.
A41: A37 | B41: Duplicate submissions | C41: Every create or submit action (Publish, Place Order, Pay, Request Payout, Accept job, Remit, Confirm) is idempotent: double-clicking, pressing Enter twice, refreshing or pressing Back and resubmitting never creates a second record or a second charge.

Sheet Test Data
A1: Test data
A2: Shared by all five module workbooks. All people, stores, numbers and addresses are fictional. Seed these products, vouchers and rates before testing, or replace them with your own and update the Test Data column on the module sheets.
A4: Accounts (created in the Account Creation test set)
A5: Ref | B5: Role | C5: Name / store | D5: Login email | E5: Password | F5: Status / notes
A6: Buyer 1 | B6: Buyer | C6: Juan Miguel Dela Cruz | D6: juanmiguel.delacruz@example.com | E6: Mamimili@2026 | F6: Active. Main buyer.
A7: Buyer 2 | B7: Buyer | C7: Ana Marie Reyes | D7: anamarie.reyes@example.com | E7: Suki#2026Ana | F7: Active. Second buyer for concurrency and access tests.
A8: Seller 1 | B8: Seller | C8: Maria Clara Handicrafts (Maria Clara Santos) | D8: mariaclara.santos@example.com | E8: Tindahan@2026 | F8: Approved. Pickup: Commonwealth, Quezon City (NCR). Main seller.
A9: Seller 2 | B9: Seller | C9: RV Gadget Hub (Roberto Villanueva) | D9: roberto.villanueva@example.com | E9: Gadget#Hub26 | F9: Approved. Pickup: Lahug, Cebu City (Visayas).
A10: Seller 3 | B10: Seller | C10: Tindahan ni Lola (test) | D10: seller.test01@example.com | E10: Tindahan@2026 | F10: Pending Approval. For the unverified-seller cases.
A11: Logistics 1 | B11: Logistics | C11: Bilis Hatid Express Inc. (Carlos Antonio Mendoza) | D11: operations@bilishatid.example.com | E11: Hatid@2026 | F11: Approved. Serves NCR and CALABARZON. Main logistics account.
A12: Logistics 2 | B12: Logistics | C12: Agila Cargo Movers Corp. (Liza Mae Fernandez) | D12: admin@agilacargo.example.com | E12: Agila#Cargo26 | F12: Approved. Serves Davao. Used for cross-company access tests.
A13: Rider 1 | B13: Rider | C13: Pedro Jose Garcia (Motorcycle, 123ABC) | D13: pedrojose.garcia@example.com | E13: Rider@2026 | F13: Active, under Logistics 1. Main rider.
A14: Rider 2 | B14: Rider | C14: Mark Anthony Bautista (Van, NBC1234) | D14: markanthony.bautista@example.com | E14: Hatid#Mark26 | F14: Active, under Logistics 1. Second rider for concurrency tests.
A15: Rider 3 | B15: Rider | C15: Ramon Cruz (Motorcycle, 456DEF) | D15: rider.test01@example.com | E15: Rider@2026 | F15: Suspended by Logistics 1. For blocked-rider cases.
A16: Admin | B16: Admin | C16: Seeded admin | D16: Use the admin account already seeded in your system | F16: Creates platform vouchers PLAT100 and FREESHIP.
A18: Buyer addresses
A19: Ref | B19: Owner | C19: Label | D19: Address | E19: Recipient / phone | F19: Notes
A20: ADDR-1 | B20: Buyer 1 | C20: Home (default) | D20: 45 Kalayaan Ave., Brgy. Central, Quezon City, Metro Manila, NCR 1100 | E20: Juan Miguel Dela Cruz / 09171234567 | F20: Zone NCR
A21: ADDR-2 | B21: Buyer 1 | C21: Office | D21: 12F Pacific Tower, 6750 Ayala Ave., Brgy. San Lorenzo, Makati City, Metro Manila, NCR 1223 | E21: Juan Miguel Dela Cruz / 09171234567 | F21: Zone NCR
A22: ADDR-3 | B22: Buyer 2 | C22: Home (default) | D22: 78 Osmeña Blvd., Brgy. Capitol Site, Cebu City, Cebu, Region VII 6000 | E22: Ana Marie Reyes / 09173456789 | F22: Zone Visayas
A23: ADDR-4 | B23: Buyer 1 | C23: Province | D23: Purok 2, Brgy. Raele, Itbayat, Batanes, Region II 3905 | E23: Juan Miguel Dela Cruz / 09171234567 | F23: Unserviceable area (no logistics zone covers it)
A25: Store categories (Seller 1)
A26: Ref | B26: Category | C26: Parent | D26: Visible | E26: Products | F26: Notes
A27: CAT-1 | B27: Bags | D27: Yes | E27: P-01
A28: CAT-2 | B28: Home Decor | D28: Yes | F28: Parent category
A29: CAT-3 | B29: Lamps | C29: Home Decor | D29: Yes | E29: P-03 | F29: Subcategory (level 2)
A30: CAT-4 | B30: Baskets | C30: Home Decor | D30: Yes | E30: P-02 | F30: Subcategory (level 2)
A31: CAT-5 | B31: Kitchen & Dining | D31: Yes | E31: P-04
A33: Products
A34: Ref | B34: Seller | C34: Product | D34: Price / variants | E34: Stock | F34: Weight and size / other
A35: P-01 | B35: Seller 1 | C35: Abaca Woven Tote Bag | D35: Color: Natural, Black × Size: S ₱199, M ₱249, L ₱299 (6 variants). SKU MCH-TOTE-<COLOR>-<SIZE> | E35: Natural-S 10, Natural-M 8, Natural-L 5, Black-S 10, Black-M 0, Black-L 3 | F35: 0.4 kg; 40 × 35 × 5 cm. Platform category: Women's Bags
A36: P-02 | B36: Seller 1 | C36: Rattan Fruit Basket | D36: ₱450.00 (no variants) | E36: 20 | F36: 0.8 kg; 30 × 30 × 15 cm. Platform category: Home & Living
A37: P-03 | B37: Seller 1 | C37: Capiz Shell Lamp | D37: ₱1,250.00 | E37: 1 (for the oversell case) | F37: 1.5 kg; 30 × 30 × 40 cm
A38: P-04 | B38: Seller 1 | C38: Banig Placemat Set of 4 | D38: ₱350.00 | E38: 0 (out of stock) | F38: 0.5 kg
A39: P-05 | B39: Seller 2 | C39: USB-C Fast Charger 20W | D39: ₱399.00 | E39: 50 | F39: 0.2 kg; 10 × 8 × 5 cm
A40: P-06 | B40: Seller 2 | C40: Wireless Earbuds X2 | D40: Color: Black, White; ₱1,499.00 each | E40: Black 10, White 10 | F40: 0.3 kg
A41: P-07 | B41: Seller 2 | C41: Power Bank 10000mAh | D41: ₱899.00; per-buyer purchase limit 2 | E41: 5 | F41: 0.4 kg
A43: Vouchers
A44: Code | B44: Owner / funded by | C44: Type | D44: Rule | E44: Limits / validity | F44: Display
A45: MCH50 | B45: Seller 1 / seller | C45: Fixed ₱50 off | D45: Min spend ₱300; all Seller 1 products | E45: 100 total, 1 per buyer; valid this month | F45: Claimable
...

Sheet Test Files
A1: Upload files to prepare
A2: Prepare these files before testing uploads. Use sample images only. The size limit is 5 MB, which is 5,120 KB or 5,242,880 bytes.
A4: File name | B4: Type | C4: Size | D4: Used for | E4: Expected result
A5: product_front.jpg | B5: JPG | C5: 1.2 MB | D5: Product image | E5: Accept
A6: product_side.png | B6: PNG | C6: 2.4 MB | D6: Product image | E6: Accept
A7: store_logo.png | B7: PNG | C7: 300 KB | D7: Store logo | E7: Accept
A8: store_banner.jpg | B8: JPG | C8: 1.8 MB | D8: Store banner | E8: Accept
A9: review_photo.jpg | B9: JPG | C9: 1.5 MB | D9: Review photo / return evidence / chat attachment | E9: Accept
A10: return_video.mp4 | B10: MP4 | C10: 8 MB | D10: Return evidence video (if videos are supported) | E10: Accept per your rule
A11: pod_photo.jpg | B11: JPG | C11: 1.1 MB | D11: Rider proof of delivery | E11: Accept
A12: size_4.9MB.jpg | B12: JPG | C12: 4.9 MB (5,138,022 bytes) | D12: Just under the size limit | E12: Accept
A13: size_5.0MB.jpg | B13: JPG | C13: 5.0 MB (5,242,880 bytes) | D13: Exactly at the size limit | E13: Accept
A14: size_5.1MB.jpg | B14: JPG | C14: 5.1 MB (5,347,738 bytes) | D14: Just over the size limit | E14: Reject
A15: price_list.docx | B15: DOCX | C15: 320 KB | D15: Wrong file type (Word document) | E15: Reject
... A17: renamed_exe.jpg | B17: JPG (really an EXE) | C17: 2.1 MB | D17: Program renamed to .jpg | E17: Reject

Sheet R1 Profile & Vehicle
A1: Test Case ID | B1: Module | C1: Test Scenario | D1: Technique | E1: Priority | F1: Preconditions | G1: Test Steps | H1: Test Data | I1: Expected Result | J1: Assumption Ref | K1: Actual Result | L1: Status | M1: Remarks
A2: RID-PROF-001 | B2: Profile, Vehicle & Documents | C2: View profile, vehicle and verification status | D2: Use Case Testing | E2: Medium | F2: Logged in as Rider 1. | G2: 1. Open My Profile. 2. Open each uploaded document. | I2: Shows Pedro Jose Garcia, license N01-23-456789, expiry 03/22/2030, Motorcycle, plate 123ABC, company Bilis Hatid Express Inc., status Active. Both documents open. | J2: A1 | K2: As expected. Shows Pedro Jose Garcia, license N01-23-456789, expiry 03/22/2030, Motorcycle, plate 123ABC, company Bilis Hatid Express Inc., status Active. Both documents open. | L2: Pass | M2: Verified by automated test RiderModulesSheetTest::test_RID_PROF_001_view_profile_vehicle_and_verification_status (PHPUnit), passed on 2026-10-19, build a5a130d.
A3: RID-PROF-002 | B3: Profile, Vehicle & Documents | C3: Update vehicle details | D3: State Transition | E3: Medium | F3: Logged in as Rider 1. | G3: 1. Change the plate number and upload a new OR/CR. 2. Save. 3. As Logistics 1, open Rider 1's record. | H3: Plate: 789GHI OR/CR: or_cr.pdf (900 KB) | I3: The change is saved and shown to Logistics 1 with the new OR/CR, flagged for re-verification. The old plate is no longer shown. | K3: As expected. The change is saved and shown to Logistics 1 with the new OR/CR, flagged for re-verification. The old plate is no longer shown. | L3: Pass | M3: Verified by automated test RiderModulesSheetTest::test_RID_PROF_002_update_vehicle_details (PHPUnit), passed on 2026-10-19, build a5a130d.
A4: RID-PROF-003 | B4: Profile, Vehicle & Documents | C4: Plate number already used | D4: Equivalence Partitioning | E4: Medium | F4: Logged in as Rider 1. | G4: 1. Change the plate to each value and save. | H4: NBC1234 nbc1234 | I4: Both are blocked as already registered. The plate stays 123ABC. | K4: Both are blocked: 'That plate number is already registered to another rider.' The plate stays 123ABC. | L4: Pass | M4: Verified by automated test RiderModulesSheetTest::test_RID_PROF_003_plate_number_already_used (PHPUnit), passed on 2026-10-19, build a5a130d.
A5: RID-PROF-004 | B5: Profile, Vehicle & Documents | C5: License expiry boundary | D5: Boundary Value Analysis | E5: High | F5: Logged in as Rider 1. | G5: 1. Set the license expiry to yesterday and save. 2. Set it to today and save. | I5: Yesterday is rejected with an expiry message. Today is accepted. | K5: Yesterday is rejected: 'Your driver's license has expired. Enter an expiry date from today onward.' Today is accepted. | L5: Pass | M5: Verified by automated test RiderModulesSheetTest::test_RID_PROF_004_license_expiry_boundary (PHPUnit), passed on 2026-10-19, build a5a130d.
A6: RID-PROF-005 | B6: Profile, Vehicle & Documents | C6: Document upload rules | D6: Boundary Value Analysis | E6: Medium | F6: Logged in as Rider 1. | G6: 1. Upload each file as the driver's license. | H6: size_5.0MB.jpg (accept) size_5.1MB.jpg (reject) price_list.docx (reject) renamed_exe.jpg (reject) | I6: Only the 5.0 MB JPG is accepted; the others are rejected and the previous document is kept. | J6: A16 | K6: Only the 5.0 MB JPG is accepted; the others are rejected ('The driver's license must be a JPG, PNG or PDF file of at most 5 MB.') and the previous document is kept. | L6: Pass | M6: Verified by automated test RiderModulesSheetTest::test_RID_PROF_005_document_upload_rules (PHPUnit), passed on 2026-10-19, build a5a130d.
A7: RID-PROF-006 | B7: Profile, Vehicle & Documents | C7: Suspended rider cannot work | D7: State Transition | E7: High | F7: Logged in as Rider 3 (Suspended). | G7: 1. Try to go Online. 2. Logistics 1 creates a job near Rider 3 and runs auto-assign. | I7: Rider 3 cannot go Online and sees a suspension message. Rider 3 receives no offer and is not selectable for manual assignment. | J7: A14 | K7: Rider 3 cannot go Online (suspended accounts are signed out). Rider 3 gets no offer and is not listed for manual assignment; a direct assignment is refused: 'Ramon Cruz is not an active rider.' | L7: Pass | M7: Verified by automated test RiderModulesSheetTest::test_RID_PROF_006_suspended_rider_cannot_work (PHPUnit), passed on 2026-10-19, build a5a130d.
A8: RID-PROF-007 | B8: Profile, Vehicle & Documents | C8: Rider cannot see another rider's profile | D8: Error Guessing | E8: High | F8: Logged in as Rider 1. | G8: 1. Change the rider ID in the profile URL or request to Rider 2's. | I8: Denied. No Rider 2 data is shown. | J8: A22 | K8: Denied: the profile URL has no rider ID (always your own), and opening another rider's document is refused. No Rider 2 data is shown. | L8: Pass | M8: Verified by automated test RiderModulesSheetTest::test_RID_PROF_007_rider_cannot_see_another_riders_profile (PHPUnit), passed on 2026-10-19, build a5a130d.

Sheet R2 Availability
A1: Test Case ID | B1: Module | C1: Test Scenario | D1: Technique | E1: Priority | F1: Preconditions | G1: Test Steps | H1: Test Data | I1: Expected Result | J1: Assumption Ref | K1: Actual Result | L1: Status | M1: Remarks
A2: RID-AVAIL-001 | B2: Availability | C2: Go Online | D2: State Transition | E2: High | F2: Logged in as Rider 1, Offline. Rider 2 is Offline. | G2: 1. Toggle Online. 2. As Logistics 1, open the rider list. 3. Seller 1 has a COD order for P-02 to ADDR-1 (total ₱500.00) marked Ready for Pickup. Run auto-assign. | I2: Logistics 1 sees Rider 1 as Online within a few seconds. Rider 1 receives the offer. | J2: A14 | K2: As expected. Logistics 1 sees Rider 1 as Online within a few seconds. Rider 1 receives the offer. | L2: Pass | M2: Verified by automated test RiderModulesSheetTest::test_RID_AVAIL_001_go_online (PHPUnit), passed on 2026-10-19, build a5a130d.
A3: RID-AVAIL-002 | B3: Availability | C3: Go Offline | D3: State Transition | E3: High | F3: Logged in as Rider 1 (Active, Online, 0 active jobs). Rider 2 is Online. | G3: 1. Toggle Offline. 2. Logistics 1 runs auto-assign for a new job. 3. Logistics 1 opens Manual Assign. | I3: Rider 1 receives no offer, and is not listed in Manual Assign. The job goes to Rider 2. | J3: A14 | K3: As expected. Rider 1 receives no offer, and is not listed in Manual Assign. The job goes to Rider 2. | L3: Pass | M3: Verified by automated test RiderModulesSheetTest::test_RID_AVAIL_002_go_offline (PHPUnit), passed on 2026-10-19, build a5a130d.
A4: RID-AVAIL-003 | B4: Availability | C4: Go Offline with an active job | D4: State Transition | E4: Medium | F4: Logged in as Rider 1 (Active, Online, 0 active jobs). Rider 1 has a Picked Up parcel. | G4: 1. Toggle Offline. 2. Open My Jobs. | I4: Offline is allowed. The Picked Up job stays with Rider 1 and can still be delivered. No new offers arrive. | J4: A14 | K4: As expected. Offline is allowed. The Picked Up job stays with Rider 1 and can still be delivered. No new offers arrive. | L4: Pass | M4: Verified by automated test RiderModulesSheetTest::test_RID_AVAIL_003_go_offline_with_an_active_job (PHPUnit), passed on 2026-10-19, build a5a130d.
A5: RID-AVAIL-004 | B5: Availability | C5: Offline after logout or session timeout | D5: Error Guessing | E5: Low | F5: Logged in as Rider 1 (Active, Online, 0 active jobs). | G5: 1. Log out. 2. As Logistics 1, check the rider list and run auto-assign. | I5: Rider 1 shows Offline and gets no offer. | J5: A22 | K5: As expected. Rider 1 shows Offline and gets no offer. | L5: Pass | M5: Verified by automated test RiderModulesSheetTest::test_RID_AVAIL_004_offline_after_logout_or_session_timeout (PHPUnit), passed on 2026-10-19, build a5a130d.

Sheet R3 Job Assignment
A1: Test Case ID | B1: Module | C1: Test Scenario | D1: Technique | E1: Priority | F1: Preconditions | G1: Test Steps | H1: Test Data | I1: Expected Result | J1: Assumption Ref | K1: Actual Result | L1: Status | M1: Remarks
A2: RID-JOB-001 | B2: Job Assignment | C2: View and accept a job | D2: Use Case Testing | E2: High | F2: Logged in as Rider 1 (Active, Online, 0 active jobs). Seller 1 has a COD order for P-02 to ADDR-1 (total ₱500.00) marked Ready for Pickup. The job is offered to Rider 1. | G2: 1. Open the offer. 2. Check the details. 3. Click Accept. | I2: The offer shows pickup (Seller 1, Commonwealth, QC), drop-off area (Brgy. Central, QC), COD ₱500.00 and pay ₱30.00 pickup. After Accept, the job is Assigned to Rider 1 and Logistics 1 sees Rider 1 as the assignee. | J2: A10, A33 | K2: As expected. The offer shows pickup (Seller 1, Commonwealth, QC), drop-off area (Brgy. Central, QC), COD ₱500.00 and pay ₱30.00 pickup. After Accept, the job is Assigned to Rider 1 and Logistics 1 sees Rider 1 as the assignee. | L2: Pass | M2: Verified by automated test RiderModulesSheetTest::test_RID_JOB_001_view_and_accept_a_job (PHPUnit), passed on 2026-10-19, build a5a130d.
A3: RID-JOB-002 | B3: Job Assignment | C3: Decline a job | D3: Use Case Testing | E3: Medium | F3: Logged in as Rider 1 (Active, Online, 0 active jobs). A job is offered; Rider 2 is Online. | G3: 1. Click Decline. | I3: The offer disappears for Rider 1 and is offered to Rider 2. Rider 1 is not assigned. | J3: A14 | K3: As expected. The offer disappears for Rider 1 and is offered to Rider 2. Rider 1 is not assigned. | L3: Pass | M3: Verified by automated test RiderModulesSheetTest::test_RID_JOB_002_decline_a_job (PHPUnit), passed on 2026-10-19, build a5a130d.
A4: RID-JOB-003 | B4: Job Assignment | C4: Offer timeout | D4: Boundary Value Analysis | E4: High | F4: Logged in as Rider 1 (Active, Online, 0 active jobs). | G4: 1. On one offer, click Accept at 55–59 seconds. 2. On another offer, wait 61 seconds and click Accept. | I4: The first Accept succeeds. After 60 seconds the second offer is expired; Accept is disabled or rejected and the job goes to the next rider. | J4: A14 | K4: The Accept at 59 seconds succeeds. After 60 seconds the second offer is expired; Accept is rejected ('This job offer has expired.') and the job is offered to Rider 2. | L4: Pass | M4: Verified by automated test RiderModulesSheetTest::test_RID_JOB_003_offer_timeout (PHPUnit), passed on 2026-10-19, build a5a130d.
A5: RID-JOB-004 | B5: Job Assignment | C5: Job goes to Unassigned after 3 declines | D5: State Transition | E5: Medium | F5: Riders 1 and 2 and one more rider are Online. | G5: 1. Each of the 3 riders declines the same job in turn. 2. As Logistics 1, open the Unassigned queue. | I5: After the 3rd decline the job is in the Unassigned queue and no longer offered automatically. | J5: A14 | K5: As expected. After the 3rd decline the job is in the Unassigned queue and no longer offered automatically. | L5: Pass | M5: Verified by automated test RiderModulesSheetTest::test_RID_JOB_004_job_goes_to_unassigned_after_3_declines (PHPUnit), passed on 2026-10-19, build a5a130d.
A6: RID-JOB-005 | B6: Job Assignment | C6: Accept and manual assignment at the same moment | D6: Error Guessing | E6: High | F6: Logged in as Rider 1 (Active, Online, 0 active jobs). A job is offered to Rider 1. Rider 2 is Online with 0 jobs. | G6: 1. At the same moment, Rider 1 clicks Accept and Logistics 1 manually assigns the job to Rider 2. 2. Check both riders' job lists and Logistics 1's view. | I6: Exactly one rider has the job, and Logistics 1 shows that same rider. The other side gets a clear 'already assigned' message. No duplicate job exists. | J6: A37 | K6: Exactly one rider has the job (whoever is first; here Rider 1) and Logistics 1 shows that rider. The other side gets 'This job was already assigned to Pedro Jose Garcia.' No duplicate job exists. | L6: Pass | M6: Verified by automated test RiderModulesSheetTest::test_RID_JOB_005_accept_and_manual_assignment_at_the_same_moment (PHPUnit), passed on 2026-10-19, build a5a130d.
A7: RID-JOB-006 | B7: Job Assignment | C7: Concurrent job limit | D7: Boundary Value Analysis | E7: High | F7: Logged in as Rider 1 (Active, Online, 0 active jobs). Rider 1 has 2 active jobs. | G7: 1. Accept a 3rd job. 2. Logistics 1 runs auto-assign and tries manual assign for a 4th job to Rider 1. | I7: The 3rd is accepted. Rider 1 gets no 4th offer, and manual assign of a 4th is blocked. | J7: A14 | K7: The 3rd is accepted. Rider 1 gets no 4th offer, and manual assign of a 4th is blocked: 'Pedro Jose Garcia already has 3 active jobs (the limit).' | L7: Pass | M7: Verified by automated test RiderModulesSheetTest::test_RID_JOB_006_concurrent_job_limit (PHPUnit), passed on 2026-10-19, build a5a130d.
A8: RID-JOB-007 | B8: Job Assignment | C8: Cannot accept another company's job | D8: Error Guessing | E8: High | F8: Logged in as Rider 1 (Active, Online, 0 active jobs). | G8: 1. Send an accept request with a job ID belonging to Logistics 2. | I8: Rejected (403 or not found). The job is unchanged. | J8: A22 | K8: Rejected ('Job offer not found.'; the pickup is outside Rider 1's areas). The job is unchanged. | L8: Pass | M8: Verified by automated test RiderModulesSheetTest::test_RID_JOB_007_cannot_accept_another_companys_job (PHPUnit), passed on 2026-10-19, build a5a130d.

Sheet R4 Pickup
A1: Test Case ID | B1: Module | C1: Test Scenario | D1: Technique | E1: Priority | F1: Preconditions | G1: Test Steps | H1: Test Data | I1: Expected Result | J1: Assumption Ref | K1: Actual Result | L1: Status | M1: Remarks
A2: RID-PICK-001 | B2: Pickup | C2: Pickup details shown | D2: Use Case Testing | E2: Medium | F2: Logged in as Rider 1 (Active, Online, 0 active jobs). The pickup job above is Assigned to Rider 1. | G2: 1. Open the job. | I2: Shows Seller 1's name, pickup address, contact number, tracking number and 1 parcel. | K2: As expected. Shows Seller 1's name, pickup address, contact number, tracking number and 1 parcel. | L2: Pass | M2: Verified by automated test RiderModulesSheetTest::test_RID_PICK_001_pickup_details_shown (PHPUnit), passed on 2026-10-19, build a5a130d.
A3: RID-PICK-002 | B3: Pickup | C3: Confirm pickup by scanning | D3: State Transition | E3: High | F3: Logged in as Rider 1 (Active, Online, 0 active jobs). | G3: 1. At Seller 1, scan the waybill barcode. 2. Check the job, Seller 1's order and Buyer 1's order. | H3: Tracking number from the waybill | I3: Status is Picked Up with the scan time in all three views. Buyer 1's order moves to To Receive. Seller 1 can no longer cancel. Rider 1 earns ₱30.00. | J3: A6, A10, A33 | K3: Status Picked Up with the scan time in the job, Seller 1's and Buyer 1's orders. Buyer 1's order moves to To Receive. Seller 1 can no longer cancel. Rider 1 earns ₱30.00. | L3: Pass | M3: Verified by automated test RiderModulesSheetTest::test_RID_PICK_002_confirm_pickup_by_scanning (PHPUnit), passed on 2026-10-19, build a5a130d.
A4: RID-PICK-003 | B4: Pickup | C4: Confirm pickup by typing the tracking number | D4: State Transition | E4: Medium | F4: Logged in as Rider 1 (Active, Online, 0 active jobs). | G4: 1. Type the tracking number instead of scanning. | I4: Status becomes Picked Up exactly as with a scan. | K4: As expected. Status becomes Picked Up exactly as with a scan. | L4: Pass | M4: Verified by automated test RiderModulesSheetTest::test_RID_PICK_003_confirm_pickup_by_typing_the_tracking_number (PHPUnit), passed on 2026-10-19, build a5a130d.
A5: RID-PICK-004 | B5: Pickup | C5: Wrong tracking number | D5: Equivalence Partitioning | E5: High | F5: Logged in as Rider 1 (Active, Online, 0 active jobs). | G5: 1. Scan or type another order's tracking number. 2. Type a random value. | H5: TRK-0000000 | I5: Both are rejected with 'tracking number does not match this job'. Status stays Assigned. | K5: Both are rejected with 'The tracking number does not match this job.' Status stays Pickup Assigned. | L5: Pass | M5: Verified by automated test RiderModulesSheetTest::test_RID_PICK_004_wrong_tracking_number (PHPUnit), passed on 2026-10-19, build a5a130d.
A6: RID-PICK-005 | B6: Pickup | C6: Double scan at pickup | D6: Error Guessing | E6: Low | F6: Logged in as Rider 1 (Active, Online, 0 active jobs). | G6: 1. Scan the same waybill twice. | I6: One Picked Up event only; the second scan shows 'already picked up'. Pay counted once. | J6: A37 | K6: One Picked Up event only; the second scan shows 'This parcel was already picked up.' Pay counted once (₱30.00). | L6: Pass | M6: Verified by automated test RiderModulesSheetTest::test_RID_PICK_005_double_scan_at_pickup (PHPUnit), passed on 2026-10-19, build a5a130d.

Sheet R5 Delivery
A1: Test Case ID | B1: Module | C1: Test Scenario | D1: Technique | E1: Priority | F1: Preconditions | G1: Test Steps | H1: Test Data | I1: Expected Result | J1: Assumption Ref | K1: Actual Result | L1: Status | M1: Remarks
A2: RID-DLV-001 | B2: Delivery & Status Updates | C2: Deliver with proof in sequence | D2: State Transition | E2: High | F2: Logged in as Rider 1 (Active, Online, 0 active jobs). The P-02 parcel is At Hub and assigned to Rider 1 for delivery. | G2: 1. Mark Out for Delivery. 2. At ADDR-1, take the POD photo. 3. Ask Buyer 1 for the OTP and enter it. 4. Enter COD ₱500.00 and mark Delivered. 5. Check Buyer 1's, Seller 1's and Logistics 1's views. | H2: Photo: pod_photo.jpg OTP: from Buyer 1's order page COD: ₱500.00 | I2: Each status is shown in all views with times. After Delivered: Buyer 1 sees Delivered with the photo, Rider 1's COD balance rises by ₱500.00 and pay by ₱50.00. | J2: A10, A32, A33 | K2: As expected. Each status is shown in all views with times. After Delivered: Buyer 1 sees Delivered with the photo, Rider 1's COD balance rises by ₱500.00 and pay by ₱50.00. | L2: Pass | M2: Verified by automated test RiderModulesSheetTest::test_RID_DLV_001_deliver_with_proof_in_sequence (PHPUnit), passed on 2026-10-19, build a5a130d.
A3: RID-DLV-002 | B3: Delivery & Status Updates | C3: Skipping a status | D3: State Transition | E3: High | F3: Logged in as Rider 1 (Active, Online, 0 active jobs). A delivery job is Assigned, not yet Out for Delivery. | G3: 1. Look for Delivered. 2. Send the Delivered request directly if possible. | I3: Delivered is not available and a direct request is rejected. Status unchanged. | J3: A10 | K3: Delivered is not offered and a direct request is refused: 'This order must be moved to Out for Delivery first.' | L3: Pass | M3: Verified by automated test RiderModulesSheetTest::test_RID_DLV_002_skipping_a_status (PHPUnit), passed on 2026-10-19, build a5a130d.
A4: RID-DLV-003 | B4: Delivery & Status Updates | C4: Photo is required | D4: Equivalence Partitioning | E4: High | F4: Logged in as Rider 1 (Active, Online, 0 active jobs). A job is Out for Delivery. | G4: 1. Enter the OTP and COD without a photo and tap Delivered. 2. Attach a 5.1 MB photo. | I4: Both are blocked with a message. The status stays Out for Delivery. | J4: A16, A32 | K4: Both are blocked: 'Take a photo of the parcel with the buyer (JPG, PNG or WEBP, up to 5 MB) to mark it Delivered.' Status stays Out for Delivery. | L4: Pass | M4: Verified by automated test RiderModulesSheetTest::test_RID_DLV_003_photo_is_required (PHPUnit), passed on 2026-10-19, build a5a130d.
A5: RID-DLV-004 | B5: Delivery & Status Updates | C5: OTP checks | D5: Boundary Value Analysis | E5: High | F5: Logged in as Rider 1 (Active, Online, 0 active jobs). A job is Out for Delivery. | G5: 1. Enter 12345 (5 digits). 2. Enter a wrong 6-digit OTP 5 times. 3. Enter the correct OTP immediately after. 4. Enter it again after 15 minutes. | I5: 5 digits is rejected. Each wrong OTP is rejected. After the 5th wrong entry, entry is locked for 15 minutes (the correct OTP is also refused). After 15 minutes the correct OTP works. | J5: A32 | K5: 12345 is rejected ('Enter the buyer's 6-digit delivery OTP.'). Each wrong OTP is rejected with the tries left; the 5th locks entry for 15 minutes and the correct OTP is refused too. After 15 minutes the correct OTP works. | L5: Pass | M5: Verified by automated test RiderModulesSheetTest::test_RID_DLV_004_otp_checks (PHPUnit), passed on 2026-10-19, build a5a130d.
A6: RID-DLV-005 | B6: Delivery & Status Updates | C6: COD amount must match | D6: Boundary Value Analysis | E6: High | F6: Logged in as Rider 1 (Active, Online, 0 active jobs). COD job for ₱500.00. | G6: 1. Enter ₱499.99 and submit. 2. Enter ₱500.01 and submit. 3. Enter ₱500.00 and submit. | I6: ₱499.99 and ₱500.01 are rejected with a mismatch message. Only ₱500.00 completes delivery. | J6: A24 | K6: ₱499.99 and ₱500.01 are rejected: 'The COD amount collected must be exactly ₱500.00.' Only ₱500.00 completes delivery. | L6: Pass | M6: Verified by automated test RiderModulesSheetTest::test_RID_DLV_005_cod_amount_must_match (PHPUnit), passed on 2026-10-19, build a5a130d.
A7: RID-DLV-006 | B7: Delivery & Status Updates | C7: Prepaid order has no COD | D7: Equivalence Partitioning | E7: Medium | F7: Logged in as Rider 1 (Active, Online, 0 active jobs). Prepaid job. | G7: 1. Open the job and complete delivery. | I7: COD shows ₱0.00 / Paid; no amount is asked for, and the COD balance does not change. | K7: The job shows 'Paid online — COD ₱0.00'; no amount is asked for, and the COD balance stays ₱0.00. | L7: Pass | M7: Verified by automated test RiderModulesSheetTest::test_RID_DLV_006_prepaid_order_has_no_cod (PHPUnit), passed on 2026-10-19, build a5a130d.
A8: RID-DLV-007 | B8: Delivery & Status Updates | C8: Cannot update another rider's job | D8: Error Guessing | E8: High | F8: Logged in as Rider 1 (Active, Online, 0 active jobs). | G8: 1. Send a status update for a job assigned to Rider 2. | I8: Rejected. Rider 2's job is unchanged. | J8: A22 | K8: Rejected: 'This delivery is not assigned to you.' Rider 2's job is unchanged. | L8: Pass | M8: Verified by automated test RiderModulesSheetTest::test_RID_DLV_007_cannot_update_another_riders_job (PHPUnit), passed on 2026-10-19, build a5a130d.

Sheet R6 Failed Delivery
A1: Test Case ID | B1: Module | C1: Test Scenario | D1: Technique | E1: Priority | F1: Preconditions | G1: Test Steps | H1: Test Data | I1: Expected Result | J1: Assumption Ref | K1: Actual Result | L1: Status | M1: Remarks
A2: RID-FAIL-001 | B2: Failed Delivery | C2: Mark failed with a reason | D2: State Transition | E2: High | F2: Logged in as Rider 1 (Active, Online, 0 active jobs). A COD job is Out for Delivery. | G2: 1. Mark Failed and choose 'Buyer not home'. 2. Check Buyer 1's and Logistics 1's views. | I2: Status Failed Delivery, attempt 1 of 3, with the reason. Buyer 1 and Logistics 1 are notified. No COD is collected and pay is ₱0.00 for the attempt. | J2: A13, A23, A33 | K2: Status Delivery Failed (= Failed Delivery), attempt 1 of 3, with the reason (Buyer not available = not home). Buyer 1 and Logistics 1 are notified. No COD is collected and pay is ₱0.00. | L2: Pass | M2: Reason names per BoomBuy rule A13. Verified by automated test RiderModulesSheetTest::test_RID_FAIL_001_mark_failed_with_a_reason (PHPUnit), passed on 2026-10-19, build a5a130d.
A3: RID-FAIL-002 | B3: Failed Delivery | C3: Reason required | D3: Equivalence Partitioning | E3: Medium | F3: Logged in as Rider 1 (Active, Online, 0 active jobs). | G3: 1. Mark Failed without choosing a reason. | I3: Blocked; status unchanged. | J3: A13 | K3: Blocked: 'Please choose a reason for the failed delivery.' Status unchanged. | L3: Pass | M3: Verified by automated test RiderModulesSheetTest::test_RID_FAIL_002_reason_required (PHPUnit), passed on 2026-10-19, build a5a130d.
A4: RID-FAIL-003 | B4: Failed Delivery | C4: Refused goes straight to Return to Sender | D4: State Transition | E4: High | F4: Logged in as Rider 1 (Active, Online, 0 active jobs). Attempt 1. | G4: 1. Mark Failed with 'Refused'. | I4: Status Return to Sender immediately; no further attempt is scheduled. | J4: A13 | K4: Shown as Return to Sender immediately; rescheduling is refused (the buyer refused it). | L4: Pass | M4: Verified by automated test RiderModulesSheetTest::test_RID_FAIL_003_refused_goes_straight_to_return_to_sender (PHPUnit), passed on 2026-10-19, build a5a130d.
A5: RID-FAIL-004 | B5: Failed Delivery | C5: Attempt counter and reschedule | D5: State Transition | E5: High | F5: Attempt 1 failed (Buyer not home). | G5: 1. Logistics 1 reschedules; Rider 1 goes Out for Delivery again and delivers. | I5: The job shows attempt 2 of 3 and completes normally on success. | J5: A13 | K5: As expected. The job shows attempt 2 of 3 and completes normally on success. | L5: Pass | M5: Verified by automated test RiderModulesSheetTest::test_RID_FAIL_004_attempt_counter_and_reschedule (PHPUnit), passed on 2026-10-19, build a5a130d.
A6: RID-FAIL-005 | B6: Failed Delivery | C6: Return to Sender after the 3rd failed attempt | D6: Boundary Value Analysis | E6: High | F6: Attempts 1 and 2 failed (Buyer not home). | G6: 1. Fail attempt 3 with 'Wrong address'. | I6: Status Return to Sender. No 4th attempt is possible. Buyer 1 and Seller 1 are notified. | J6: A13 | K6: Return to Sender. No 4th attempt ('maximum delivery attempts'). Buyer 1 and Seller 1 are notified. | L6: Pass | M6: 'Wrong address' = 'Wrong or incomplete address' (A13). Verified by automated test RiderModulesSheetTest::test_RID_FAIL_005_return_to_sender_after_the_3rd_failed_attempt (PHPUnit), passed on 2026-10-19, build a5a130d.

Sheet R7 Earnings & COD
A1: Test Case ID | B1: Module | C1: Test Scenario | D1: Technique | E1: Priority | F1: Preconditions | G1: Test Steps | H1: Test Data | I1: Expected Result | J1: Assumption Ref | K1: Actual Result | L1: Status | M1: Remarks
A2: RID-EARN-001 | B2: History, Earnings & COD Remittance | C2: Delivery history | D2: Use Case Testing | E2: Medium | F2: Logged in as Rider 1 (Active, Online, 0 active jobs). Rider 1 has completed and failed jobs. | G2: 1. Open History and filter by date. | I2: Every job is listed once with date, tracking number, result and pay. | K2: As expected. Every job is listed once with date, tracking number, result and pay. | L2: Pass | M2: Verified by automated test RiderModulesSheetTest::test_RID_EARN_001_delivery_history (PHPUnit), passed on 2026-10-19, build a5a130d.
A3: RID-EARN-002 | B3: History, Earnings & COD Remittance | C3: Pay per job and daily total | D3: Use Case Testing | E3: High | F3: Logged in as Rider 1 (Active, Online, 0 active jobs). Today: 2 pickups, 3 successful deliveries, 1 failed attempt. | G3: 1. Open Earnings for today and this week. | I3: Today's total is exactly ₱210.00 (2 × ₱30 + 3 × ₱50 + 1 × ₱0). The weekly total includes it. | J3: A33 | K3: As expected. Today's total is exactly ₱210.00 (2 × ₱30 + 3 × ₱50 + 1 × ₱0). The weekly total includes it. | L3: Pass | M3: Today's jobs were set up as records (2 pickups, 3 deliveries, 1 failed attempt); totals computed by the Profit page. Verified by automated test RiderModulesSheetTest::test_RID_EARN_002_pay_per_job_and_daily_total (PHPUnit), passed on 2026-10-19, build a5a130d.
A4: RID-EARN-003 | B4: History, Earnings & COD Remittance | C4: COD balance to remit | D4: Use Case Testing | E4: High | F4: Logged in as Rider 1 (Active, Online, 0 active jobs). Collected ₱500.00 (P-02 order) and ₱1,300.00 (P-03 ₱1,250 + ₱50 shipping) today. | G4: 1. Open COD balance. | I4: Balance shows ₱1,800.00 with both orders listed. | J4: A24 | K4: As expected. Balance shows ₱1,800.00 with both orders listed. | L4: Pass | M4: P-03 weighed at 1 kg so its COD is the sheet's ₱1,300 (at 1.5 kg the sheet's own rates give ₱65 shipping). Verified by automated test RiderModulesSheetTest::test_RID_EARN_003_cod_balance_to_remit (PHPUnit), passed on 2026-10-19, build a5a130d.
A5: RID-EARN-004 | B5: History, Earnings & COD Remittance | C5: Remit COD and confirmation | D5: State Transition | E5: High | F5: Logged in as Rider 1 (Active, Online, 0 active jobs). | G5: 1. Submit a remittance of ₱1,800.00. 2. Check the balance before and after Logistics 1 confirms. | I5: Before confirmation the remittance is Pending and the balance still shows ₱1,800.00 pending. After confirmation the balance is ₱0.00. | J5: A24 | K5: As expected. Before confirmation the remittance is Pending and the balance still shows ₱1,800.00 pending. After confirmation the balance is ₱0.00. | L5: Pass | M5: P-03 weighed at 1 kg so the totals match the sheet's ₱1,800. Verified by automated test RiderModulesSheetTest::test_RID_EARN_004_remit_cod_and_confirmation (PHPUnit), passed on 2026-10-19, build a5a130d.
A6: RID-EARN-005 | B6: History, Earnings & COD Remittance | C6: Short remittance | D6: Boundary Value Analysis | E6: Medium | F6: Logged in as Rider 1 (Active, Online, 0 active jobs). | G6: 1. Submit ₱1,750.00. | I6: Logistics 1 sees a ₱50.00 shortfall flag; Rider 1's balance shows ₱50.00 outstanding after confirmation. | J6: A24 | K6: Logistics 1 sees a −₱50.00 shortfall flag; after confirmation Rider 1's balance shows ₱50.00 outstanding. | L6: Pass | M6: P-03 weighed at 1 kg so the totals match the sheet's ₱1,800. Verified by automated test RiderModulesSheetTest::test_RID_EARN_005_short_remittance (PHPUnit), passed on 2026-10-19, build a5a130d.
A7: RID-EARN-006 | B7: History, Earnings & COD Remittance | C7: Rider cannot confirm own remittance | D7: Error Guessing | E7: High | F7: Logged in as Rider 1 (Active, Online, 0 active jobs). | G7: 1. Try the Logistics confirm request directly. | I7: Rejected (403). | J7: A22, A24 | K7: Rejected (403). The remittance stays Pending. | L7: Pass | M7: Verified by automated test RiderModulesSheetTest::test_RID_EARN_006_rider_cannot_confirm_own_remittance (PHPUnit), passed on 2026-10-19, build a5a130d.
